  File "main.py", line 211
    with open(history_df_csv_file, mode='w') as h:
                                                 ^
TabError: inconsistent use of tabs and spaces in indentation
