Failure # 1 (occurred at 2021-07-13_12-09-17)
Traceback (most recent call last):
  File "/opt/conda/lib/python3.8/site-packages/ray/tune/trial_runner.py", line 702, in _process_trial
    results = self.trial_executor.fetch_result(trial)
  File "/opt/conda/lib/python3.8/site-packages/ray/tune/ray_trial_executor.py", line 686, in fetch_result
    result = ray.get(trial_future[0], timeout=DEFAULT_GET_TIMEOUT)
  File "/opt/conda/lib/python3.8/site-packages/ray/_private/client_mode_hook.py", line 47, in wrapper
    return func(*args, **kwargs)
  File "/opt/conda/lib/python3.8/site-packages/ray/worker.py", line 1481, in get
    raise value.as_instanceof_cause()
ray.exceptions.RayTaskError(UnknownError): [36mray::BlackBox.train_buffered()[39m (pid=221773, ip=172.17.0.9)
  File "python/ray/_raylet.pyx", line 505, in ray._raylet.execute_task
  File "python/ray/_raylet.pyx", line 449, in ray._raylet.execute_task.function_executor
  File "/opt/conda/lib/python3.8/site-packages/ray/_private/function_manager.py", line 556, in actor_method_executor
    return method(__ray_actor, *args, **kwargs)
  File "/opt/conda/lib/python3.8/site-packages/ray/tune/trainable.py", line 173, in train_buffered
    result = self.train()
  File "/opt/conda/lib/python3.8/site-packages/ray/tune/trainable.py", line 232, in train
    result = self.step()
  File "/opt/conda/lib/python3.8/site-packages/ray/tune/trainable.py", line 650, in step
    result = self._train()
  File "main.py", line 223, in _train
    history = model.fit(inputs[train],
  File "/opt/conda/lib/python3.8/site-packages/tensorflow/python/keras/engine/training.py", line 108, in _method_wrapper
    return method(self, *args, **kwargs)
  File "/opt/conda/lib/python3.8/site-packages/tensorflow/python/keras/engine/training.py", line 1098, in fit
    tmp_logs = train_function(iterator)
  File "/opt/conda/lib/python3.8/site-packages/tensorflow/python/eager/def_function.py", line 780, in __call__
    result = self._call(*args, **kwds)
  File "/opt/conda/lib/python3.8/site-packages/tensorflow/python/eager/def_function.py", line 840, in _call
    return self._stateless_fn(*args, **kwds)
  File "/opt/conda/lib/python3.8/site-packages/tensorflow/python/eager/function.py", line 2829, in __call__
    return graph_function._filtered_call(args, kwargs)  # pylint: disable=protected-access
  File "/opt/conda/lib/python3.8/site-packages/tensorflow/python/eager/function.py", line 1843, in _filtered_call
    return self._call_flat(
  File "/opt/conda/lib/python3.8/site-packages/tensorflow/python/eager/function.py", line 1923, in _call_flat
    return self._build_call_outputs(self._inference_function.call(
  File "/opt/conda/lib/python3.8/site-packages/tensorflow/python/eager/function.py", line 545, in call
    outputs = execute.execute(
  File "/opt/conda/lib/python3.8/site-packages/tensorflow/python/eager/execute.py", line 59, in quick_execute
    tensors = pywrap_tfe.TFE_Py_Execute(ctx._handle, device_name, op_name,
tensorflow.python.framework.errors_impl.UnknownError:  Failed to get convolution algorithm. This is probably because cuDNN failed to initialize, so try looking to see if a warning log message was printed above.
	 [[node sequential/conv2d/Conv2D (defined at main.py:223) ]] [Op:__inference_train_function_713]

Function call stack:
train_function

